Workbook

Sheet Alimenti
A1: alimento | B1: kcal | C1: carboidrati_g | D1: proteine_g | E1: grassi_g | F1: fibra_g | G1: zuccheri_g | H1: grassi_saturi_g | I1: grassi_mono_g | J1: grassi_poli_g | K1: colesterolo_mg | L1: sodio_mg | M1: potassio_mg | N1: calcio_mg | O1: fosforo_mg | P1: magnesio_mg | Q1: ferro_mg | R1: zinco_mg | S1: vit_a_ug_rae | T1: vit_c_mg | U1: vit_d_ug | V1: vit_e_mg | W1: vit_b1_mg | X1: vit_b2_mg | Y1: vit_b3_mg | Z1: vit_b6_mg | AA1: folati_ug | AB1: vit_b12_ug | AC1: categoria | AD1: id | AE1: ruolo | AF1: stato | AG1: g_per_ml | AH1: porzione_unitaria_g | AI1: porzione_unitaria_descr | AJ1: all_glutine | AK1: all_latte | AL1: int_lattosio | AM1: all_uova | AN1: all_pesce | AO1: all_crostacei | AP1: all_molluschi | AQ1: all_frutta_guscio | AR1: all_arachidi | AS1: all_soia | AT1: all_sesamo | AU1: all_sedano | AV1: all_senape | AW1: all_solfiti | AX1: all_lupini | AY1: nichel | AZ1: fodmap_alto | BA1: allergeni_sintesi | BB1: kcal_da_macro | BC1: fonte | BD1: note
A2: Latte intero | B2: 64 | C2: 4.8 | D2: 3.3 | E2: 3.6 | F2: 0 | G2: 4.8 | H2: 2.1 | I2: 1 | J2: 0.1 | K2: 11 | L2: 43 | M2: 150 | N2: 119 | O2: 93 | P2: 11 | Q2: 0.03 | R2: 0.4 | S2: 37 | T2: 1 | U2: 0.1 | V2: 0.07 | W2: 0.04 | X2: 0.18 | Y2: 0.09 | Z2: 0.04 | AA2: 5 | AB2: 0.4 | AC2: Latte e latticini | AD2: latte_intero | AE2: misto | AF2: liquido | AG2: 1.03 | AJ2: 0 | AK2: 1 | AL2: 1 | AM2: 0 | AN2: 0 | AO2: 0 | AP2: 0 | AQ2: 0 | AR2: 0 | AS2: 0 | AT2: 0 | AU2: 0 | AV2: 0 | AW2: 0 | AX2: 0 | AY2: 0 | AZ2: 1 | BA2: =_xlfn.TEXTJOIN(", ",TRUE(),IF(AJ2=1,"glutine",IF(AJ2=2,"glutine (tracce)","")),IF(AK2=1,"latte",IF(AK2=2,"latte (tracce)","")),IF(AL2=1,"lattosio",IF(AL2=2,"lattosio (tracce)","")),IF(AM2=1,"uova",IF(AM2=2,"uova (tracce)","")),IF(AN2=1,"pesce",IF(AN2=2,"pesce (tracce)","")),IF(AO2=1,"crostacei",IF(AO2=2,"crostacei (tracce)","")),IF(AP2=1,"molluschi",IF(AP2=2,"molluschi (tracce)","")),IF(AQ2=1,"frutta a guscio",IF(AQ2=2,"frutta a guscio (tracce)","")),IF(AR2=1,"arachidi",IF(AR2=2,"arachidi (tracce)","")),IF(AS2=1,"soia",IF(AS2=2,"soia (tracce)","")),IF(AT2=1,"sesamo",IF(AT2=2,"sesamo (tracce)","")),IF(AU2=1,"sedano",IF(AU2=2,"sedano (tracce)","")),IF(AV2=1,"senape",IF(AV2=2,"senape (tracce)","")),IF(AW2=1,"solfiti",IF(AW2=2,"solfiti (tracce)","")),IF(AX2=1,"lupini",IF(AX2=2,"lupini (tracce)","")),IF(AY2=1,"nichel",IF(AY2=2,"nichel (tracce)","")),IF(AZ2=1,"FODMAP",IF(AZ2=2,"FODMAP (tracce)",""))) -> latte, lattosio, FODMAP | BB2: =ROUND(4*C2+4*D2+9*E2+2*N(F2),0) -> 65 | BC2: CREA – Tabelle di composizione degli alimenti
A3: Latte parzialmente scremato | B3: 46 | C3: 5 | D3: 3.5 | E3: 1.5 | F3: 0 | G3: 5 | H3: 1 | I3: 0.4 | J3: 0.06 | K3: 7 | L3: 44 | M3: 150 | N3: 120 | O3: 94 | P3: 11 | Q3: 0.03 | R3: 0.4 | S3: 18 | T3: 1 | U3: 0.03 | V3: 0.04 | W3: 0.04 | X3: 0.18 | Y3: 0.09 | Z3: 0.04 | AA3: 5 | AB3: 0.4 | AC3: Latte e latticini | AD3: latte_parzialmente_scremato | AE3: misto | AF3: liquido | AG3: 1.03 | AJ3: 0 | AK3: 1 | AL3: 1 | AM3: 0 | AN3: 0 | AO3: 0 | AP3: 0 | AQ3: 0 | AR3: 0 | AS3: 0 | AT3: 0 | AU3: 0 | AV3: 0 | AW3: 0 | AX3: 0 | AY3: 0 | AZ3: 1 | BA3: =_xlfn.TEXTJOIN(", ",TRUE(),IF(AJ3=1,"glutine",IF(AJ3=2,"glutine (tracce)","")),IF(AK3=1,"latte",IF(AK3=2,"latte (tracce)","")),IF(AL3=1,"lattosio",IF(AL3=2,"lattosio (tracce)","")),IF(AM3=1,"uova",IF(AM3=2,"uova (tracce)","")),IF(AN3=1,"pesce",IF(AN3=2,"pesce (tracce)","")),IF(AO3=1,"crostacei",IF(AO3=2,"crostacei (tracce)","")),IF(AP3=1,"molluschi",IF(AP3=2,"molluschi (tracce)","")),IF(AQ3=1,"frutta a guscio",IF(AQ3=2,"frutta a guscio (tracce)","")),IF(AR3=1,"arachidi",IF(AR3=2,"arachidi (tracce)","")),IF(AS3=1,"soia",IF(AS3=2,"soia (tracce)","")),IF(AT3=1,"sesamo",IF(AT3=2,"sesamo (tracce)","")),IF(AU3=1,"sedano",IF(AU3=2,"sedano (tracce)","")),IF(AV3=1,"senape",IF(AV3=2,"senape (tracce)","")),IF(AW3=1,"solfiti",IF(AW3=2,"solfiti (tracce)","")),IF(AX3=1,"lupini",IF(AX3=2,"lupini (tracce)","")),IF(AY3=1,"nichel",IF(AY3=2,"nichel (tracce)","")),IF(AZ3=1,"FODMAP",IF(AZ3=2,"FODMAP (tracce)",""))) -> latte, lattosio, FODMAP | BB3: =ROUND(4*C3+4*D3+9*E3+2*N(F3),0) -> 48 | BC3: CREA – Tabelle di composizione degli alimenti
A4: Latte scremato | B4: 34 | C4: 5 | D4: 3.4 | E4: 0.2 | F4: 0 | G4: 5 | H4: 0.1 | I4: 0.05 | J4: 0.01 | K4: 2 | L4: 42 | M4: 156 | N4: 122 | O4: 101 | P4: 11 | Q4: 0.03 | R4: 0.4 | S4: 1 | T4: 1 | U4: 0 | V4: 0.01 | W4: 0.04 | X4: 0.18 | Y4: 0.09 | Z4: 0.04 | AA4: 5 | AB4: 0.5 | AC4: Latte e latticini | AD4: latte_scremato | AE4: proteine | AF4: liquido | AG4: 1.03 | AJ4: 0 | AK4: 1 | AL4: 1 | AM4: 0 | AN4: 0 | AO4: 0 | AP4: 0 | AQ4: 0 | AR4: 0 | AS4: 0 | AT4: 0 | AU4: 0 | AV4: 0 | AW4: 0 | AX4: 0 | AY4: 0 | AZ4: 1 | BA4: =_xlfn.TEXTJOIN(", ",TRUE(),IF(AJ4=1,"glutine",IF(AJ4=2,"glutine (tracce)","")),IF(AK4=1,"latte",IF(AK4=2,"latte (tracce)","")),IF(AL4=1,"lattosio",IF(AL4=2,"lattosio (tracce)","")),IF(AM4=1,"uova",IF(AM4=2,"uova (tracce)","")),IF(AN4=1,"pesce",IF(AN4=2,"pesce (tracce)","")),IF(AO4=1,"crostacei",IF(AO4=2,"crostacei (tracce)","")),IF(AP4=1,"molluschi",IF(AP4=2,"molluschi (tracce)","")),IF(AQ4=1,"frutta a guscio",IF(AQ4=2,"frutta a guscio (tracce)","")),IF(AR4=1,"arachidi",IF(AR4=2,"arachidi (tracce)","")),IF(AS4=1,"soia",IF(AS4=2,"soia (tracce)","")),IF(AT4=1,"sesamo",IF(AT4=2,"sesamo (tracce)","")),IF(AU4=1,"sedano",IF(AU4=2,"sedano (tracce)","")),IF(AV4=1,"senape",IF(AV4=2,"senape (tracce)","")),IF(AW4=1,"solfiti",IF(AW4=2,"solfiti (tracce)","")),IF(AX4=1,"lupini",IF(AX4=2,"lupini (tracce)","")),IF(AY4=1,"nichel",IF(AY4=2,"nichel (tracce)","")),IF(AZ4=1,"FODMAP",IF(AZ4=2,"FODMAP (tracce)",""))) -> latte, lattosio, FODMAP | BB4: =ROUND(4*C4+4*D4+9*E4+2*N(F4),0) -> 35 | BC4: CREA – Tabelle di composizione degli alimenti
A5: Yogurt bianco intero | B5: 61 | C5: 4.7 | D5: 3.5 | E5: 3.3 | F5: 0 | G5: 4.7 | H5: 2.1 | I5: 0.9 | J5: 0.1 | K5: 13 | L5: 46 | M5: 155 | N5: 121 | O5: 95 | P5: 12 | Q5: 0.05 | R5: 0.6 | S5: 27 | T5: 0.5 | U5: 0.1 | V5: 0.06 | W5: 0.03 | X5: 0.14 | Y5: 0.08 | Z5: 0.03 | AA5: 7 | AB5: 0.37 | AC5: Latte e latticini | AD5: yogurt_bianco_intero | AE5: misto | AF5: crudo | AJ5: 0 | AK5: 1 | AL5: 1 | AM5: 0 | AN5: 0 | AO5: 0 | AP5: 0 | AQ5: 0 | AR5: 0 | AS5: 0 | AT5: 0 | AU5: 0 | AV5: 0 | AW5: 0 | AX5: 0 | AY5: 0 | AZ5: 1 | BA5: =_xlfn.TEXTJOIN(", ",TRUE(),IF(AJ5=1,"glutine",IF(AJ5=2,"glutine (tracce)","")),IF(AK5=1,"latte",IF(AK5=2,"latte (tracce)","")),IF(AL5=1,"lattosio",IF(AL5=2,"lattosio (tracce)","")),IF(AM5=1,"uova",IF(AM5=2,"uova (tracce)","")),IF(AN5=1,"pesce",IF(AN5=2,"pesce (tracce)","")),IF(AO5=1,"crostacei",IF(AO5=2,"crostacei (tracce)","")),IF(AP5=1,"molluschi",IF(AP5=2,"molluschi (tracce)","")),IF(AQ5=1,"frutta a guscio",IF(AQ5=2,"frutta a guscio (tracce)","")),IF(AR5=1,"arachidi",IF(AR5=2,"arachidi (tracce)","")),IF(AS5=1,"soia",IF(AS5=2,"soia (tracce)","")),IF(AT5=1,"sesamo",IF(AT5=2,"sesamo (tracce)","")),IF(AU5=1,"sedano",IF(AU5=2,"sedano (tracce)","")),IF(AV5=1,"senape",IF(AV5=2,"senape (tracce)","")),IF(AW5=1,"solfiti",IF(AW5=2,"solfiti (tracce)","")),IF(AX5=1,"lupini",IF(AX5=2,"lupini (tracce)","")),IF(AY5=1,"nichel",IF(AY5=2,"nichel (tracce)","")),IF(AZ5=1,"FODMAP",IF(AZ5=2,"FODMAP (tracce)",""))) -> latte, lattosio, FODMAP | BB5: =ROUND(4*C5+4*D5+9*E5+2*N(F5),0) -> 63 | BC5: USDA FoodData Central – SR Legacy
A6: Yogurt greco 0% grassi | B6: 59 | C6: 3.6 | D6: 10.2 | E6: 0.4 | F6: 0 | G6: 3.2 | H6: 0.12 | I6: 0.05 | J6: 0.01 | K6: 5 | L6: 36 | M6: 141 | N6: 110 | O6: 135 | P6: 11 | Q6: 0.07 | R6: 0.52 | S6: 1 | T6: 0 | U6: 0 | V6: 0.01 | W6: 0.02 | X6: 0.28 | Y6: 0.21 | Z6: 0.06 | AA6: 7 | AB6: 0.75 | AC6: Latte e latticini | AD6: yogurt_greco_0_grassi | AE6: proteine | AF6: crudo | AH6: 170 | AI6: 1 vasetto | AJ6: 0 | AK6: 1 | AL6: 1 | AM6: 0 | AN6: 0 | AO6: 0 | AP6: 0 | AQ6: 0 | AR6: 0 | AS6: 0 | AT6: 0 | AU6: 0 | AV6: 0 | AW6: 0 | AX6: 0 | AY6: 0 | AZ6: 0 | BA6: =_xlfn.TEXTJOIN(", ",TRUE(),IF(AJ6=1,"glutine",IF(AJ6=2,"glutine (tracce)","")),IF(AK6=1,"latte",IF(AK6=2,"latte (tracce)","")),IF(AL6=1,"lattosio",IF(AL6=2,"lattosio (tracce)","")),IF(AM6=1,"uova",IF(AM6=2,"uova (tracce)","")),IF(AN6=1,"pesce",IF(AN6=2,"pesce (tracce)","")),IF(AO6=1,"crostacei",IF(AO6=2,"crostacei (tracce)","")),IF(AP6=1,"molluschi",IF(AP6=2,"molluschi (tracce)","")),IF(AQ6=1,"frutta a guscio",IF(AQ6=2,"frutta a guscio (tracce)","")),IF(AR6=1,"arachidi",IF(AR6=2,"arachidi (tracce)","")),IF(AS6=1,"soia",IF(AS6=2,"soia (tracce)","")),IF(AT6=1,"sesamo",IF(AT6=2,"sesamo (tracce)","")),IF(AU6=1,"sedano",IF(AU6=2,"sedano (tracce)","")),IF(AV6=1,"senape",IF(AV6=2,"senape (tracce)","")),IF(AW6=1,"solfiti",IF(AW6=2,"solfiti (tracce)","")),IF(AX6=1,"lupini",IF(AX6=2,"lupini (tracce)","")),IF(AY6=1,"nichel",IF(AY6=2,"nichel (tracce)","")),IF(AZ6=1,"FODMAP",IF(AZ6=2,"FODMAP (tracce)",""))) -> latte, lattosio | BB6: =ROUND(4*C6+4*D6+9*E6+2*N(F6),0) -> 59 | BC6: USDA FoodData Central – SR Legacy
A7: Yogurt greco 2% grassi | B7: 73 | C7: 3.9 | D7: 9.9 | E7: 1.9 | F7: 0 | G7: 3.6 | H7: 1.2 | I7: 0.5 | J7: 0.1 | K7: 10 | L7: 34 | M7: 141 | N7: 115 | O7: 136 | P7: 11 | Q7: 0.07 | R7: 0.5 | S7: 15 | T7: 0 | U7: 0 | V7: 0.03 | W7: 0.02 | X7: 0.25 | Y7: 0.2 | Z7: 0.06 | AA7: 7 | AB7: 0.75 | AC7: Latte e latticini | AD7: yogurt_greco_2_grassi | AE7: proteine | AF7: crudo | AH7: 170 | AI7: 1 vasetto | AJ7: 0 | AK7: 1 | AL7: 1 | AM7: 0 | AN7: 0 | AO7: 0 | AP7: 0 | AQ7: 0 | AR7: 0 | AS7: 0 | AT7: 0 | AU7: 0 | AV7: 0 | AW7: 0 | AX7: 0 | AY7: 0 | AZ7: 0 | BA7: =_xlfn.TEXTJOIN(", ",TRUE(),IF(AJ7=1,"glutine",IF(AJ7=2,"glutine (tracce)","")),IF(AK7=1,"latte",IF(AK7=2,"latte (tracce)","")),IF(AL7=1,"lattosio",IF(AL7=2,"lattosio (tracce)","")),IF(AM7=1,"uova",IF(AM7=2,"uova (tracce)","")),IF(AN7=1,"pesce",IF(AN7=2,"pesce (tracce)","")),IF(AO7=1,"crostacei",IF(AO7=2,"crostacei (tracce)","")),IF(AP7=1,"molluschi",IF(AP7=2,"molluschi (tracce)","")),IF(AQ7=1,"frutta a guscio",IF(AQ7=2,"frutta a guscio (tracce)","")),IF(AR7=1,"arachidi",IF(AR7=2,"arachidi (tracce)","")),IF(AS7=1,"soia",IF(AS7=2,"soia (tracce)","")),IF(AT7=1,"sesamo",IF(AT7=2,"sesamo (tracce)","")),IF(AU7=1,"sedano",IF(AU7=2,"sedano (tracce)","")),IF(AV7=1,"senape",IF(AV7=2,"senape (tracce)","")),IF(AW7=1,"solfiti",IF(AW7=2,"solfiti (tracce)","")),IF(AX7=1,"lupini",IF(AX7=2,"lupini (tracce)","")),IF(AY7=1,"nichel",IF(AY7=2,"nichel (tracce)","")),IF(AZ7=1,"FODMAP",IF(AZ7=2,"FODMAP (tracce)",""))) -> latte, lattosio | BB7: =ROUND(4*C7+4*D7+9*E7+2*N(F7),0) -> 72 | BC7: USDA FoodData Central – SR Legacy
A8: Skyr naturale | B8: 63 | C8: 4 | D8: 11 | E8: 0.2 | F8: 0 | G8: 4 | H8: 0.1 | I8: 0.05 | J8: 0.01 | K8: 3 | L8: 40 | M8: 150 | N8: 120 | O8: 140 | P8: 11 | Q8: 0.05 | R8: 0.5 | S8: 2 | T8: 0 | U8: 0 | V8: 0 | W8: 0.03 | X8: 0.25 | Y8: 0.1 | Z8: 0.05 | AA8: 6 | AB8: 0.6 | AC8: Latte e latticini | AD8: skyr_naturale | AE8: proteine | AF8: crudo | AH8: 150 | AI8: 1 vasetto | AJ8: 0 | AK8: 1 | AL8: 1 | AM8: 0 | AN8: 0 | AO8: 0 | AP8: 0 | AQ8: 0 | AR8: 0 | AS8: 0 | AT8: 0 | AU8: 0 | AV8: 0 | AW8: 0 | AX8: 0 | AY8: 0 | AZ8: 0 | BA8: =_xlfn.TEXTJOIN(", ",TRUE(),IF(AJ8=1,"glutine",IF(AJ8=2,"glutine (tracce)","")),IF(AK8=1,"latte",IF(AK8=2,"latte (tracce)","")),IF(AL8=1,"lattosio",IF(AL8=2,"lattosio (tracce)","")),IF(AM8=1,"uova",IF(AM8=2,"uova (tracce)","")),IF(AN8=1,"pesce",IF(AN8=2,"pesce (tracce)","")),IF(AO8=1,"crostacei",IF(AO8=2,"crostacei (tracce)","")),IF(AP8=1,"molluschi",IF(AP8=2,"molluschi (tracce)","")),IF(AQ8=1,"frutta a guscio",IF(AQ8=2,"frutta a guscio (tracce)","")),IF(AR8=1,"arachidi",IF(AR8=2,"arachidi (tracce)","")),IF(AS8=1,"soia",IF(AS8=2,"soia (tracce)","")),IF(AT8=1,"sesamo",IF(AT8=2,"sesamo (tracce)","")),IF(AU8=1,"sedano",IF(AU8=2,"sedano (tracce)","")),IF(AV8=1,"senape",IF(AV8=2,"senape (tracce)","")),IF(AW8=1,"solfiti",IF(AW8=2,"solfiti (tracce)","")),IF(AX8=1,"lupini",IF(AX8=2,"lupini (tracce)","")),IF(AY8=1,"nichel",IF(AY8=2,"nichel (tracce)","")),IF(AZ8=1,"FODMAP",IF(AZ8=2,"FODMAP (tracce)",""))) -> latte, lattosio | BB8: =ROUND(4*C8+4*D8+9*E8+2*N(F8),0) -> 62 | BC8: Media etichette prodotti commerciali (IT)
A9: Kefir di latte (parz. scremato) | B9: 41 | C9: 4.5 | D9: 3.8 | E9: 1 | F9: 0 | G9: 4.6 | H9: 0.6 | I9: 0.25 | J9: 0.04 | K9: 5 | L9: 40 | M9: 164 | N9: 130 | O9: 105 | P9: 12 | Q9: 0.04 | R9: 0.46 | S9: 20 | T9: 0.2 | U9: 0.1 | V9: 0.02 | W9: 0.04 | X9: 0.17 | Y9: 0.07 | Z9: 0.03 | AA9: 5 | AB9: 0.27 | AC9: Latte e latticini | AD9: kefir_di_latte_parz_scremato | AE9: misto | AF9: liquido | AG9: 1.03 | AJ9: 0 | AK9: 1 | AL9: 1 | AM9: 0 | AN9: 0 | AO9: 0 | AP9: 0 | AQ9: 0 | AR9: 0 | AS9: 0 | AT9: 0 | AU9: 0 | AV9: 0 | AW9: 0 | AX9: 0 | AY9: 0 | AZ9: 0 | BA9: =_xlfn.TEXTJOIN(", ",TRUE(),IF(AJ9=1,"glutine",IF(AJ9=2,"glutine (tracce)","")),IF(AK9=1,"latte",IF(AK9=2,"latte (tracce)","")),IF(AL9=1,"lattosio",IF(AL9=2,"lattosio (tracce)","")),IF(AM9=1,"uova",IF(AM9=2,"uova (tracce)","")),IF(AN9=1,"pesce",IF(AN9=2,"pesce (tracce)","")),IF(AO9=1,"crostacei",IF(AO9=2,"crostacei (tracce)","")),IF(AP9=1,"molluschi",IF(AP9=2,"molluschi (tracce)","")),IF(AQ9=1,"frutta a guscio",IF(AQ9=2,"frutta a guscio (tracce)","")),IF(AR9=1,"arachidi",IF(AR9=2,"arachidi (tracce)","")),IF(AS9=1,"soia",IF(AS9=2,"soia (tracce)","")),IF(AT9=1,"sesamo",IF(AT9=2,"sesamo (tracce)","")),IF(AU9=1,"sedano",IF(AU9=2,"sedano (tracce)","")),IF(AV9=1,"senape",IF(AV9=2,"senape (tracce)","")),IF(AW9=1,"solfiti",IF(AW9=2,"solfiti (tracce)","")),IF(AX9=1,"lupini",IF(AX9=2,"lupini (tracce)","")),IF(AY9=1,"nichel",IF(AY9=2,"nichel (tracce)","")),IF(AZ9=1,"FODMAP",IF(AZ9=2,"FODMAP (tracce)",""))) -> latte, lattosio | BB9: =ROUND(4*C9+4*D9+9*E9+2*N(F9),0) -> 42 | BC9: USDA FoodData Central – SR Legacy | BD9: Lattosio in parte fermentato: spesso ben tollerato
A10: Dessert proteico (pudding high protein) | B10: 79 | C10: 6.2 | D10: 10 | E10: 1.5 | F10: 0.4 | G10: 4.4 | H10: 1 | L10: 60 | AC10: Latte e latticini | AD10: dessert_proteico_pudding_high_protein | AE10: proteine | AF10: pronto | AH10: 200 | AI10: 1 vasetto | AJ10: 0 | AK10: 1 | AL10: 1 | AM10: 0 | AN10: 0 | AO10: 0 | AP10: 0 | AQ10: 0 | AR10: 0 | AS10: 0 | AT10: 0 | AU10: 0 | AV10: 0 | AW10: 0 | AX10: 0 | AY10: 0 | AZ10: 0 | BA10: =_xlfn.TEXTJOIN(", ",TRUE(),IF(AJ10=1,"glutine",IF(AJ10=2,"glutine (tracce)","")),IF(AK10=1,"latte",IF(AK10=2,"latte (tracce)","")),IF(AL10=1,"lattosio",IF(AL10=2,"lattosio (tracce)","")),IF(AM10=1,"uova",IF(AM10=2,"uova (tracce)","")),IF(AN10=1,"pesce",IF(AN10=2,"pesce (tracce)","")),IF(AO10=1,"crostacei",IF(AO10=2,"crostacei (tracce)","")),IF(AP10=1,"molluschi",IF(AP10=2,"molluschi (tracce)","")),IF(AQ10=1,"frutta a guscio",IF(AQ10=2,"frutta a guscio (tracce)","")),IF(AR10=1,"arachidi",IF(AR10=2,"arachidi (tracce)","")),IF(AS10=1,"soia",IF(AS10=2,"soia (tracce)","")),IF(AT10=1,"sesamo",IF(AT10=2,"sesamo (tracce)","")),IF(AU10=1,"sedano",IF(AU10=2,"sedano (tracce)","")),IF(AV10=1,"senape",IF(AV10=2,"senape (tracce)","")),IF(AW10=1,"solfiti",IF(AW10=2,"solfiti (tracce)","")),IF(AX10=1,"lupini",IF(AX10=2,"lupini (tracce)","")),IF(AY10=1,"nichel",IF(AY10=2,"nichel (tracce)","")),IF(AZ10=1,"FODMAP",IF(AZ10=2,"FODMAP (tracce)",""))) -> latte, lattosio | BB10: =ROUND(4*C10+4*D10+9*E10+2*N(F10),0) -> 79 | BC10: Media etichette prodotti commerciali (IT) | BD10: Tipo Ehrmann High Protein / Milk Pro: verificare etichetta
A11: Fiocchi di latte | B11: 98 | C11: 3.4 | D11: 11.1 | E11: 4.3 | F11: 0 | G11: 2.7 | H11: 1.7 | I11: 0.78 | J11: 0.12 | K11: 17 | L11: 364 | M11: 104 | N11: 83 | O11: 159 | P11: 8 | Q11: 0.07 | R11: 0.4 | S11: 37 | T11: 0 | U11: 0.1 | V11: 0.08 | W11: 0.03 | X11: 0.16 | Y11: 0.1 | Z11: 0.05 | AA11: 12 | AB11: 0.43 | AC11: Latte e latticini | AD11: fiocchi_di_latte | AE11: proteine | AF11: crudo | AH11: 200 | AI11: 1 vaschetta | AJ11: 0 | AK11: 1 | AL11: 1 | AM11: 0 | AN11: 0 | AO11: 0 | AP11: 0 | AQ11: 0 | AR11: 0 | AS11: 0 | AT11: 0 | AU11: 0 | AV11: 0 | AW11: 0 | AX11: 0 | AY11: 0 | AZ11: 1 | BA11: =_xlfn.TEXTJOIN(", ",TRUE(),IF(AJ11=1,"glutine",IF(AJ11=2,"glutine (tracce)","")),IF(AK11=1,"latte",IF(AK11=2,"latte (tracce)","")),IF(AL11=1,"lattosio",IF(AL11=2,"lattosio (tracce)","")),IF(AM11=1,"uova",IF(AM11=2,"uova (tracce)","")),IF(AN11=1,"pesce",IF(AN11=2,"pesce (tracce)","")),IF(AO11=1,"crostacei",IF(AO11=2,"crostacei (tracce)","")),IF(AP11=1,"molluschi",IF(AP11=2,"molluschi (tracce)","")),IF(AQ11=1,"frutta a guscio",IF(AQ11=2,"frutta a guscio (tracce)","")),IF(AR11=1,"arachidi",IF(AR11=2,"arachidi (tracce)","")),IF(AS11=1,"soia",IF(AS11=2,"soia (tracce)","")),IF(AT11=1,"sesamo",IF(AT11=2,"sesamo (tracce)","")),IF(AU11=1,"sedano",IF(AU11=2,"sedano (tracce)","")),IF(AV11=1,"senape",IF(AV11=2,"senape (tracce)","")),IF(AW11=1,"solfiti",IF(AW11=2,"solfiti (tracce)","")),IF(AX11=1,"lupini",IF(AX11=2,"lupini (tracce)","")),IF(AY11=1,"nichel",IF(AY11=2,"nichel (tracce)","")),IF(AZ11=1,"FODMAP",IF(AZ11=2,"FODMAP (tracce)",""))) -> latte, lattosio, FODMAP | BB11: =ROUND(4*C11+4*D11+9*E11+2*N(F11),0) -> 97 | BC11: USDA FoodData Central – SR Legacy
A12: Ricotta vaccina | B12: 146 | C12: 3.5 | D12: 8.8 | E12: 10.9 | F12: 0 | G12: 3.5 | H12: 6.9 | I12: 3 | J12: 0.3 | K12: 50 | L12: 78 | M12: 119 | N12: 295 | O12: 237 | P12: 11 | Q12: 0.2 | R12: 1.2 | S12: 120 | T12: 0 | U12: 0.2 | V12: 0.1 | W12: 0.02 | X12: 0.19 | Y12: 0.1 | Z12: 0.04 | AA12: 12 | AB12: 0.3 | AC12: Latte e latticini | AD12: ricotta_vaccina | AE12: misto | AF12: crudo | AJ12: 0 | AK12: 1 | AL12: 1 | AM12: 0 | AN12: 0 | AO12: 0 | AP12: 0 | AQ12: 0 | AR12: 0 | AS12: 0 | AT12: 0 | AU12: 0 | AV12: 0 | AW12: 0 | AX12: 0 | AY12: 0 | AZ12: 1 | BA12: =_xlfn.TEXTJOIN(", ",TRUE(),IF(AJ12=1,"glutine",IF(AJ12=2,"glutine (tracce)","")),IF(AK12=1,"latte",IF(AK12=2,"latte (tracce)","")),IF(AL12=1,"lattosio",IF(AL12=2,"lattosio (tracce)","")),IF(AM12=1,"uova",IF(AM12=2,"uova (tracce)","")),IF(AN12=1,"pesce",IF(AN12=2,"pesce (tracce)","")),IF(AO12=1,"crostacei",IF(AO12=2,"crostacei (tracce)","")),IF(AP12=1,"molluschi",IF(AP12=2,"molluschi (tracce)","")),IF(AQ12=1,"frutta a guscio",IF(AQ12=2,"frutta a guscio (tracce)","")),IF(AR12=1,"arachidi",IF(AR12=2,"arachidi (tracce)","")),IF(AS12=1,"soia",IF(AS12=2,"soia (tracce)","")),IF(AT12=1,"sesamo",IF(AT12=2,"sesamo (tracce)","")),IF(AU12=1,"sedano",IF(AU12=2,"sedano (tracce)","")),IF(AV12=1,"senape",IF(AV12=2,"senape (tracce)","")),IF(AW12=1,"solfiti",IF(AW12=2,"solfiti (tracce)","")),IF(AX12=1,"lupini",IF(AX12=2,"lupini (tracce)","")),IF(AY12=1,"nichel",IF(AY12=2,"nichel (tracce)","")),IF(AZ12=1,"FODMAP",IF(AZ12=2,"FODMAP (tracce)",""))) -> latte, lattosio, FODMAP | BB12: =ROUND(4*C12+4*D12+9*E12+2*N(F12),0) -> 147 | BC12: CREA – Tabelle di composizione degli alimenti
A13: Ricotta light | B13: 98 | C13: 3.8 | D13: 9.5 | E13: 5 | F13: 0 | G13: 3.8 | H13: 3.3 | K13: 18 | L13: 80 | AC13: Latte e latticini | AD13: ricotta_light | AE13: proteine | AF13: crudo | AJ13: 0 | AK13: 1 | AL13: 1 | AM13: 0 | AN13: 0 | AO13: 0 | AP13: 0 | AQ13: 0 | AR13: 0 | AS13: 0 | AT13: 0 | AU13: 0 | AV13: 0 | AW13: 0 | AX13: 0 | AY13: 0 | AZ13: 1 | BA13: =_xlfn.TEXTJOIN(", ",TRUE(),IF(AJ13=1,"glutine",IF(AJ13=2,"glutine (tracce)","")),IF(AK13=1,"latte",IF(AK13=2,"latte (tracce)","")),IF(AL13=1,"lattosio",IF(AL13=2,"lattosio (tracce)","")),IF(AM13=1,"uova",IF(AM13=2,"uova (tracce)","")),IF(AN13=1,"pesce",IF(AN13=2,"pesce (tracce)","")),IF(AO13=1,"crostacei",IF(AO13=2,"crostacei (tracce)","")),IF(AP13=1,"molluschi",IF(AP13=2,"molluschi (tracce)","")),IF(AQ13=1,"frutta a guscio",IF(AQ13=2,"frutta a guscio (tracce)","")),IF(AR13=1,"arachidi",IF(AR13=2,"arachidi (tracce)","")),IF(AS13=1,"soia",IF(AS13=2,"soia (tracce)","")),IF(AT13=1,"sesamo",IF(AT13=2,"sesamo (tracce)","")),IF(AU13=1,"sedano",IF(AU13=2,"sedano (tracce)","")),IF(AV13=1,"senape",IF(AV13=2,"senape (tracce)","")),IF(AW13=1,"solfiti",IF(AW13=2,"solfiti (tracce)","")),IF(AX13=1,"lupini",IF(AX13=2,"lupini (tracce)","")),IF(AY13=1,"nichel",IF(AY13=2,"nichel (tracce)","")),IF(AZ13=1,"FODMAP",IF(AZ13=2,"FODMAP (tracce)",""))) -> latte, lattosio, FODMAP | BB13: =ROUND(4*C13+4*D13+9*E13+2*N(F13),0) -> 98 | BC13: Media etichette prodotti commerciali (IT)
A14: Mozzarella vaccina (fior di latte) | B14: 253 | C14: 0.7 | D14: 18.7 | E14: 19.5 | F14: 0 | G14: 0.7 | H14: 12 | I14: 5 | J14: 0.6 | K14: 46 | L14: 196 | M14: 102 | N14: 350 | O14: 350 | P14: 19 | Q14: 0.2 | R14: 2.3 | S14: 179 | T14: 0 | U14: 0.3 | V14: 0.4 | W14: 0.02 | X14: 0.2 | Y14: 0.1 | Z14: 0.04 | AA14: 7 | AB14: 1 | AC14: Latte e latticini | AD14: mozzarella_vaccina_fior_di_latte | AE14: misto | AF14: crudo | AH14: 125 | AI14: 1 mozzarella | AJ14: 0 | AK14: 1 | AL14: 1 | AM14: 0 | AN14: 0 | AO14: 0 | AP14: 0 | AQ14: 0 | AR14: 0 | AS14: 0 | AT14: 0 | AU14: 0 | AV14: 0 | AW14: 0 | AX14: 0 | AY14: 0 | AZ14: 0 | BA14: =_xlfn.TEXTJOIN(", ",TRUE(),IF(AJ14=1,"glutine",IF(AJ14=2,"glutine (tracce)","")),IF(AK14=1,"latte",IF(AK14=2,"latte (tracce)","")),IF(AL14=1,"lattosio",IF(AL14=2,"lattosio (tracce)","")),IF(AM14=1,"uova",IF(AM14=2,"uova (tracce)","")),IF(AN14=1,"pesce",IF(AN14=2,"pesce (tracce)","")),IF(AO14=1,"crostacei",IF(AO14=2,"crostacei (tracce)","")),IF(AP14=1,"molluschi",IF(AP14=2,"molluschi (tracce)","")),IF(AQ14=1,"frutta a guscio",IF(AQ14=2,"frutta a guscio (tracce)","")),IF(AR14=1,"arachidi",IF(AR14=2,"arachidi (tracce)","")),IF(AS14=1,"soia",IF(AS14=2,"soia (tracce)","")),IF(AT14=1,"sesamo",IF(AT14=2,"sesamo (tracce)","")),IF(AU14=1,"sedano",IF(AU14=2,"sedano (tracce)","")),IF(AV14=1,"senape",IF(AV14=2,"senape (tracce)","")),IF(AW14=1,"solfiti",IF(AW14=2,"solfiti (tracce)","")),IF(AX14=1,"lupini",IF(AX14=2,"lupini (tracce)","")),IF(AY14=1,"nichel",IF(AY14=2,"nichel (tracce)","")),IF(AZ14=1,"FODMAP",IF(AZ14=2,"FODMAP (tracce)",""))) -> latte, lattosio | BB14: =ROUND(4*C14+4*D14+9*E14+2*N(F14),0) -> 253 | BC14: CREA – Tabelle di composizione degli alimenti
A15: Mozzarella light | B15: 160 | C15: 1 | D15: 19.5 | E15: 8.8 | F15: 0 | G15: 1 | H15: 6 | K15: 30 | L15: 200 | AC15: Latte e latticini | AD15: mozzarella_light | AE15: proteine | AF15: crudo | AH15: 100 | AI15: 1 mozzarella light | AJ15: 0 | AK15: 1 | AL15: 1 | AM15: 0 | AN15: 0 | AO15: 0 | AP15: 0 | AQ15: 0 | AR15: 0 | AS15: 0 | AT15: 0 | AU15: 0 | AV15: 0 | AW15: 0 | AX15: 0 | AY15: 0 | AZ15: 0 | BA15: =_xlfn.TEXTJOIN(", ",TRUE(),IF(AJ15=1,"glutine",IF(AJ15=2,"glutine (tracce)","")),IF(AK15=1,"latte",IF(AK15=2,"latte (tracce)","")),IF(AL15=1,"lattosio",IF(AL15=2,"lattosio (tracce)","")),IF(AM15=1,"uova",IF(AM15=2,"uova (tracce)","")),IF(AN15=1,"pesce",IF(AN15=2,"pesce (tracce)","")),IF(AO15=1,"crostacei",IF(AO15=2,"crostacei (tracce)","")),IF(AP15=1,"molluschi",IF(AP15=2,"molluschi (tracce)","")),IF(AQ15=1,"frutta a guscio",IF(AQ15=2,"frutta a guscio (tracce)","")),IF(AR15=1,"arachidi",IF(AR15=2,"arachidi (tracce)","")),IF(AS15=1,"soia",IF(AS15=2,"soia (tracce)","")),IF(AT15=1,"sesamo",IF(AT15=2,"sesamo (tracce)","")),IF(AU15=1,"sedano",IF(AU15=2,"sedano (tracce)","")),IF(AV15=1,"senape",IF(AV15=2,"senape (tracce)","")),IF(AW15=1,"solfiti",IF(AW15=2,"solfiti (tracce)","")),IF(AX15=1,"lupini",IF(AX15=2,"lupini (tracce)","")),IF(AY15=1,"nichel",IF(AY15=2,"nichel (tracce)","")),IF(AZ15=1,"FODMAP",IF(AZ15=2,"FODMAP (tracce)",""))) -> latte, lattosio | BB15: =ROUND(4*C15+4*D15+9*E15+2*N(F15),0) -> 161 | BC15: Media etichette prodotti commerciali (IT)
A16: Parmigiano Reggiano | B16: 392 | C16: 0 | D16: 33.5 | E16: 28.1 | F16: 0 | G16: 0 | H16: 18.4 | I16: 8 | J16: 0.9 | K16: 91 | L16: 600 | M16: 100 | N16: 1160 | O16: 680 | P16: 43 | Q16: 0.7 | R16: 4 | S16: 270 | T16: 0 | U16: 0.6 | V16: 0.6 | W16: 0.03 | X16: 0.37 | Y16: 0.06 | Z16: 0.09 | AA16: 7 | AB16: 1.2 | AC16: Latte e latticini | AD16: parmigiano_reggiano | AE16: misto | AF16: stagionato | AJ16: 0 | AK16: 1 | AL16: 0 | AM16: 0 | AN16: 0 | AO16: 0 | AP16: 0 | AQ16: 0 | AR16: 0 | AS16: 0 | AT16: 0 | AU16: 0 | AV16: 0 | AW16: 0 | AX16: 0 | AY16: 0 | AZ16: 0 | BA16: =_xlfn.TEXTJOIN(", ",TRUE(),IF(AJ16=1,"glutine",IF(AJ16=2,"glutine (tracce)","")),IF(AK16=1,"latte",IF(AK16=2,"latte (tracce)","")),IF(AL16=1,"lattosio",IF(AL16=2,"lattosio (tracce)","")),IF(AM16=1,"uova",IF(AM16=2,"uova (tracce)","")),IF(AN16=1,"pesce",IF(AN16=2,"pesce (tracce)","")),IF(AO16=1,"crostacei",IF(AO16=2,"crostacei (tracce)","")),IF(AP16=1,"molluschi",IF(AP16=2,"molluschi (tracce)","")),IF(AQ16=1,"frutta a guscio",IF(AQ16=2,"frutta a guscio (tracce)","")),IF(AR16=1,"arachidi",IF(AR16=2,"arachidi (tracce)","")),IF(AS16=1,"soia",IF(AS16=2,"soia (tracce)","")),IF(AT16=1,"sesamo",IF(AT16=2,"sesamo (tracce)","")),IF(AU16=1,"sedano",IF(AU16=2,"sedano (tracce)","")),IF(AV16=1,"senape",IF(AV16=2,"senape (tracce)","")),IF(AW16=1,"solfiti",IF(AW16=2,"solfiti (tracce)","")),IF(AX16=1,"lupini",IF(AX16=2,"lupini (tracce)","")),IF(AY16=1,"nichel",IF(AY16=2,"nichel (tracce)","")),IF(AZ16=1,"FODMAP",IF(AZ16=2,"FODMAP (tracce)",""))) -> latte | BB16: =ROUND(4*C16+4*D16+9*E16+2*N(F16),0) -> 387 | BC16: CREA – Tabelle di composizione degli alimenti | BD16: Naturalmente privo di lattosio
A17: Grana Padano | B17: 398 | C17: 0 | D17: 33 | E17: 29 | F17: 0 | G17: 0 | H17: 18.5 | I17: 8.5 | J17: 1 | K17: 98 | L17: 600 | M17: 120 | N17: 1165 | O17: 692 | P17: 63 | Q17: 0.3 | R17: 4 | S17: 270 | T17: 0 | U17: 0.6 | V17: 0.6 | W17: 0.03 | X17: 0.36 | Y17: 0.06 | Z17: 0.09 | AA17: 7 | AB17: 1.2 | AC17: Latte e latticini | AD17: grana_padano | AE17: misto | AF17: stagionato | AJ17: 0 | AK17: 1 | AL17: 0 | AM17: 0 | AN17: 0 | AO17: 0 | AP17: 0 | AQ17: 0 | AR17: 0 | AS17: 0 | AT17: 0 | AU17: 0 | AV17: 0 | AW17: 0 | AX17: 0 | AY17: 0 | AZ17: 0 | BA17: =_xlfn.TEXTJOIN(", ",TRUE(),IF(AJ17=1,"glutine",IF(AJ17=2,"glutine (tracce)","")),IF(AK17=1,"latte",IF(AK17=2,"latte (tracce)","")),IF(AL17=1,"lattosio",IF(AL17=2,"lattosio (tracce)","")),IF(AM17=1,"uova",IF(AM17=2,"uova (tracce)","")),IF(AN17=1,"pesce",IF(AN17=2,"pesce (tracce)","")),IF(AO17=1,"crostacei",IF(AO17=2,"crostacei (tracce)","")),IF(AP17=1,"molluschi",IF(AP17=2,"molluschi (tracce)","")),IF(AQ17=1,"frutta a guscio",IF(AQ17=2,"frutta a guscio (tracce)","")),IF(AR17=1,"arachidi",IF(AR17=2,"arachidi (tracce)","")),IF(AS17=1,"soia",IF(AS17=2,"soia (tracce)","")),IF(AT17=1,"sesamo",IF(AT17=2,"sesamo (tracce)","")),IF(AU17=1,"sedano",IF(AU17=2,"sedano (tracce)","")),IF(AV17=1,"senape",IF(AV17=2,"senape (tracce)","")),IF(AW17=1,"solfiti",IF(AW17=2,"solfiti (tracce)","")),IF(AX17=1,"lupini",IF(AX17=2,"lupini (tracce)","")),IF(AY17=1,"nichel",IF(AY17=2,"nichel (tracce)","")),IF(AZ17=1,"FODMAP",IF(AZ17=2,"FODMAP (tracce)",""))) -> latte | BB17: =ROUND(4*C17+4*D17+9*E17+2*N(F17),0) -> 393 | BC17: CREA – Tabelle di composizione degli alimenti | BD17: Naturalmente privo di lattosio (contiene lisozima da uovo)
A18: Feta | B18: 264 | C18: 4.1 | D18: 14.2 | E18: 21.3 | F18: 0 | G18: 4.1 | H18: 15 | I18: 4.6 | J18: 0.6 | K18: 89 | L18: 1116 | M18: 62 | N18: 493 | O18: 337 | P18: 19 | Q18: 0.65 | R18: 2.88 | S18: 125 | T18: 0 | U18: 0.4 | V18: 0.18 | W18: 0.15 | X18: 0.84 | Y18: 0.99 | Z18: 0.42 | AA18: 32 | AB18: 1.69 | AC18: Latte e latticini | AD18: feta | AE18: misto | AF18: crudo | AJ18: 0 | AK18: 1 | AL18: 1 | AM18: 0 | AN18: 0 | AO18: 0 | AP18: 0 | AQ18: 0 | AR18: 0 | AS18: 0 | AT18: 0 | AU18: 0 | AV18: 0 | AW18: 0 | AX18: 0 | AY18: 0 | AZ18: 0 | BA18: =_xlfn.TEXTJOIN(", ",TRUE(),IF(AJ18=1,"glutine",IF(AJ18=2,"glutine (tracce)","")),IF(AK18=1,"latte",IF(AK18=2,"latte (tracce)","")),IF(AL18=1,"lattosio",IF(AL18=2,"lattosio (tracce)","")),IF(AM18=1,"uova",IF(AM18=2,"uova (tracce)","")),IF(AN18=1,"pesce",IF(AN18=2,"pesce (tracce)","")),IF(AO18=1,"crostacei",IF(AO18=2,"crostacei (tracce)","")),IF(AP18=1,"molluschi",IF(AP18=2,"molluschi (tracce)","")),IF(AQ18=1,"frutta a guscio",IF(AQ18=2,"frutta a guscio (tracce)","")),IF(AR18=1,"arachidi",IF(AR18=2,"arachidi (tracce)","")),IF(AS18=1,"soia",IF(AS18=2,"soia (tracce)","")),IF(AT18=1,"sesamo",IF(AT18=2,"sesamo (tracce)","")),IF(AU18=1,"sedano",IF(AU18=2,"sedano (tracce)","")),IF(AV18=1,"senape",IF(AV18=2,"senape (tracce)","")),IF(AW18=1,"solfiti",IF(AW18=2,"solfiti (tracce)","")),IF(AX18=1,"lupini",IF(AX18=2,"lupini (tracce)","")),IF(AY18=1,"nichel",IF(AY18=2,"nichel (tracce)","")),IF(AZ18=1,"FODMAP",IF(AZ18=2,"FODMAP (tracce)",""))) -> latte, lattosio | BB18: =ROUND(4*C18+4*D18+9*E18+2*N(F18),0) -> 265 | BC18: USDA FoodData Central – SR Legacy
A19: Uovo intero | B19: 143 | C19: 0.7 | D19: 12.6 | E19: 9.5 | F19: 0 | G19: 0.4 | H19: 3.1 | I19: 3.7 | J19: 1.9 | K19: 372 | L19: 142 | M19: 138 | N19: 56 | O19: 198 | P19: 12 | Q19: 1.75 | R19: 1.29 | S19: 160 | T19: 0 | U19: 2 | V19: 1.05 | W19: 0.04 | X19: 0.46 | Y19: 0.08 | Z19: 0.17 | AA19: 47 | AB19: 0.89 | AC19: Uova | AD19: uovo_intero | AE19: proteine | AF19: crudo | AH19: 55 | AI19: 1 uovo medio (senza guscio) | AJ19: 0 | AK19: 0 | AL19: 0 | AM19: 1 | AN19: 0 | AO19: 0 | AP19: 0 | AQ19: 0 | AR19: 0 | AS19: 0 | AT19: 0 | AU19: 0 | AV19: 0 | AW19: 0 | AX19: 0 | AY19: 0 | AZ19: 0 | BA19: =_xlfn.TEXTJOIN(", ",TRUE(),IF(AJ19=1,"glutine",IF(AJ19=2,"glutine (tracce)","")),IF(AK19=1,"latte",IF(AK19=2,"latte (tracce)","")),IF(AL19=1,"lattosio",IF(AL19=2,"lattosio (tracce)","")),IF(AM19=1,"uova",IF(AM19=2,"uova (tracce)","")),IF(AN19=1,"pesce",IF(AN19=2,"pesce (tracce)","")),IF(AO19=1,"crostacei",IF(AO19=2,"crostacei (tracce)","")),IF(AP19=1,"molluschi",IF(AP19=2,"molluschi (tracce)","")),IF(AQ19=1,"frutta a guscio",IF(AQ19=2,"frutta a guscio (tracce)","")),IF(AR19=1,"arachidi",IF(AR19=2,"arachidi (tracce)","")),IF(AS19=1,"soia",IF(AS19=2,"soia (tracce)","")),IF(AT19=1,"sesamo",IF(AT19=2,"sesamo (tracce)","")),IF(AU19=1,"sedano",IF(AU19=2,"sedano (tracce)","")),IF(AV19=1,"senape",IF(AV19=2,"senape (tracce)","")),IF(AW19=1,"solfiti",IF(AW19=2,"solfiti (tracce)","")),IF(AX19=1,"lupini",IF(AX19=2,"lupini (tracce)","")),IF(AY19=1,"nichel",IF(AY19=2,"nichel (tracce)","")),IF(AZ19=1,"FODMAP",IF(AZ19=2,"FODMAP (tracce)",""))) -> uova | BB19: =ROUND(4*C19+4*D19+9*E19+2*N(F19),0) -> 139 | BC19: USDA FoodData Central – SR Legacy
A20: Albume d'uovo | B20: 52 | C20: 0.7 | D20: 10.9 | E20: 0.2 | F20: 0 | G20: 0.7 | H20: 0 | I20: 0 | J20: 0 | K20: 0 | L20: 166 | M20: 163 | N20: 7 | O20: 15 | P20: 11 | Q20: 0.08 | R20: 0.03 | S20: 0 | T20: 0 | U20: 0 | V20: 0 | W20: 0 | X20: 0.44 | Y20: 0.1 | Z20: 0 | AA20: 4 | AB20: 0.09 | AC20: Uova | AD20: albume_d_uovo | AE20: proteine | AF20: crudo | AG20: 1.03 | AH20: 33 | AI20: 1 albume | AJ20: 0 | AK20: 0 | AL20: 0 | AM20: 1 | AN20: 0 | AO20: 0 | AP20: 0 | AQ20: 0 | AR20: 0 | AS20: 0 | AT20: 0 | AU20: 0 | AV20: 0 | AW20: 0 | AX20: 0 | AY20: 0 | AZ20: 0 | BA20: =_xlfn.TEXTJOIN(", ",TRUE(),IF(AJ20=1,"glutine",IF(AJ20=2,"glutine (tracce)","")),IF(AK20=1,"latte",IF(AK20=2,"latte (tracce)","")),IF(AL20=1,"lattosio",IF(AL20=2,"lattosio (tracce)","")),IF(AM20=1,"uova",IF(AM20=2,"uova (tracce)","")),IF(AN20=1,"pesce",IF(AN20=2,"pesce (tracce)","")),IF(AO20=1,"crostacei",IF(AO20=2,"crostacei (tracce)","")),IF(AP20=1,"molluschi",IF(AP20=2,"molluschi (tracce)","")),IF(AQ20=1,"frutta a guscio",IF(AQ20=2,"frutta a guscio (tracce)","")),IF(AR20=1,"arachidi",IF(AR20=2,"arachidi (tracce)","")),IF(AS20=1,"soia",IF(AS20=2,"soia (tracce)","")),IF(AT20=1,"sesamo",IF(AT20=2,"sesamo (tracce)","")),IF(AU20=1,"sedano",IF(AU20=2,"sedano (tracce)","")),IF(AV20=1,"senape",IF(AV20=2,"senape (tracce)","")),IF(AW20=1,"solfiti",IF(AW20=2,"solfiti (tracce)","")),IF(AX20=1,"lupini",IF(AX20=2,"lupini (tracce)","")),IF(AY20=1,"nichel",IF(AY20=2,"nichel (tracce)","")),IF(AZ20=1,"FODMAP",IF(AZ20=2,"FODMAP (tracce)",""))) -> uova | BB20: =ROUND(4*C20+4*D20+9*E20+2*N(F20),0) -> 48 | BC20: USDA FoodData Central – SR Legacy
A21: Albume liquido pastorizzato (brick) | B21: 45 | C21: 0.7 | D21: 10.5 | E21: 0.2 | F21: 0 | G21: 0.7 | H21: 0 | I21: 0 | J21: 0 | K21: 0 | L21: 160 | M21: 150 | N21: 7 | O21: 15 | P21: 11 | Q21: 0.08 | R21: 0.03 | S21: 0 | T21: 0 | U21: 0 | V21: 0 | W21: 0 | X21: 0.4 | Y21: 0.1 | Z21: 0 | AA21: 4 | AB21: 0.09 | AC21: Uova | AD21: albume_liquido_pastorizzato_brick | AE21: proteine | AF21: crudo | AG21: 1.03 | AJ21: 0 | AK21: 0 | AL21: 0 | AM21: 1 | AN21: 0 | AO21: 0 | AP21: 0 | AQ21: 0 | AR21: 0 | AS21: 0 | AT21: 0 | AU21: 0 | AV21: 0 | AW21: 0 | AX21: 0 | AY21: 0 | AZ21: 0 | BA21: =_xlfn.TEXTJOIN(", ",TRUE(),IF(AJ21=1,"glutine",IF(AJ21=2,"glutine (tracce)","")),IF(AK21=1,"latte",IF(AK21=2,"latte (tracce)","")),IF(AL21=1,"lattosio",IF(AL21=2,"lattosio (tracce)","")),IF(AM21=1,"uova",IF(AM21=2,"uova (tracce)","")),IF(AN21=1,"pesce",IF(AN21=2,"pesce (tracce)","")),IF(AO21=1,"crostacei",IF(AO21=2,"crostacei (tracce)","")),IF(AP21=1,"molluschi",IF(AP21=2,"molluschi (tracce)","")),IF(AQ21=1,"frutta a guscio",IF(AQ21=2,"frutta a guscio (tracce)","")),IF(AR21=1,"arachidi",IF(AR21=2,"arachidi (tracce)","")),IF(AS21=1,"soia",IF(AS21=2,"soia (tracce)","")),IF(AT21=1,"sesamo",IF(AT21=2,"sesamo (tracce)","")),IF(AU21=1,"sedano",IF(AU21=2,"sedano (tracce)","")),IF(AV21=1,"senape",IF(AV21=2,"senape (tracce)","")),IF(AW21=1,"solfiti",IF(AW21=2,"solfiti (tracce)","")),IF(AX21=1,"lupini",IF(AX21=2,"lupini (tracce)","")),IF(AY21=1,"nichel",IF(AY21=2,"nichel (tracce)","")),IF(AZ21=1,"FODMAP",IF(AZ21=2,"FODMAP (tracce)",""))) -> uova | BB21: =ROUND(4*C21+4*D21+9*E21+2*N(F21),0) -> 47 | BC21: Media etichette prodotti commerciali (IT)
A22: Tuorlo d'uovo | B22: 322 | C22: 3.6 | D22: 15.9 | E22: 26.5 | F22: 0 | G22: 0.6 | H22: 9.6 | I22: 11.7 | J22: 4.2 | K22: 1085 | L22: 48 | M22: 109 | N22: 129 | O22: 390 | P22: 5 | Q22: 2.73 | R22: 2.3 | S22: 381 | T22: 0 | U22: 5.4 | V22: 2.58 | W22: 0.18 | X22: 0.53 | Y22: 0.02 | Z22: 0.35 | AA22: 146 | AB22: 1.95 | AC22: Uova | AD22: tuorlo_d_uovo | AE22: grassi | AF22: crudo | AH22: 17 | AI22: 1 tuorlo | AJ22: 0 | AK22: 0 | AL22: 0 | AM22: 1 | AN22: 0 | AO22: 0 | AP22: 0 | AQ22: 0 | AR22: 0 | AS22: 0 | AT22: 0 | AU22: 0 | AV22: 0 | AW22: 0 | AX22: 0 | AY22: 0 | AZ22: 0 | BA22: =_xlfn.TEXTJOIN(", ",TRUE(),IF(AJ22=1,"glutine",IF(AJ22=2,"glutine (tracce)","")),IF(AK22=1,"latte",IF(AK22=2,"latte (tracce)","")),IF(AL22=1,"lattosio",IF(AL22=2,"lattosio (tracce)","")),IF(AM22=1,"uova",IF(AM22=2,"uova (tracce)","")),IF(AN22=1,"pesce",IF(AN22=2,"pesce (tracce)","")),IF(AO22=1,"crostacei",IF(AO22=2,"crostacei (tracce)","")),IF(AP22=1,"molluschi",IF(AP22=2,"molluschi (tracce)","")),IF(AQ22=1,"frutta a guscio",IF(AQ22=2,"frutta a guscio (tracce)","")),IF(AR22=1,"arachidi",IF(AR22=2,"arachidi (tracce)","")),IF(AS22=1,"soia",IF(AS22=2,"soia (tracce)","")),IF(AT22=1,"sesamo",IF(AT22=2,"sesamo (tracce)","")),IF(AU22=1,"sedano",IF(AU22=2,"sedano (tracce)","")),IF(AV22=1,"senape",IF(AV22=2,"senape (tracce)","")),IF(AW22=1,"solfiti",IF(AW22=2,"solfiti (tracce)","")),IF(AX22=1,"lupini",IF(AX22=2,"lupini (tracce)","")),IF(AY22=1,"nichel",IF(AY22=2,"nichel (tracce)","")),IF(AZ22=1,"FODMAP",IF(AZ22=2,"FODMAP (tracce)",""))) -> uova | BB22: =ROUND(4*C22+4*D22+9*E22+2*N(F22),0) -> 317 | BC22: USDA FoodData Central – SR Legacy
A23: Petto di pollo (senza pelle) | B23: 100 | C23: 0 | D23: 23.3 | E23: 0.8 | F23: 0 | G23: 0 | H23: 0.25 | I23: 0.3 | J23: 0.2 | K23: 60 | L23: 33 | M23: 370 | N23: 4 | O23: 210 | P23: 29 | Q23: 0.4 | R23: 0.7 | S23: 6 | T23: 0 | U23: 0.1 | V23: 0.2 | W23: 0.07 | X23: 0.12 | Y23: 10.6 | Z23: 0.6 | AA23: 4 | AB23: 0.4 | AC23: Carni | AD23: petto_di_pollo_senza_pelle | AE23: proteine | AF23: crudo | AJ23: 0 | AK23: 0 | AL23: 0 | AM23: 0 | AN23: 0 | AO23: 0 | AP23: 0 | AQ23: 0 | AR23: 0 | AS23: 0 | AT23: 0 | AU23: 0 | AV23: 0 | AW23: 0 | AX23: 0 | AY23: 0 | AZ23: 0 | BA23: =_xlfn.TEXTJOIN(", ",TRUE(),IF(AJ23=1,"glutine",IF(AJ23=2,"glutine (tracce)","")),IF(AK23=1,"latte",IF(AK23=2,"latte (tracce)","")),IF(AL23=1,"lattosio",IF(AL23=2,"lattosio (tracce)","")),IF(AM23=1,"uova",IF(AM23=2,"uova (tracce)","")),IF(AN23=1,"pesce",IF(AN23=2,"pesce (tracce)","")),IF(AO23=1,"crostacei",IF(AO23=2,"crostacei (tracce)","")),IF(AP23=1,"molluschi",IF(AP23=2,"molluschi (tracce)","")),IF(AQ23=1,"frutta a guscio",IF(AQ23=2,"frutta a guscio (tracce)","")),IF(AR23=1,"arachidi",IF(AR23=2,"arachidi (tracce)","")),IF(AS23=1,"soia",IF(AS23=2,"soia (tracce)","")),IF(AT23=1,"sesamo",IF(AT23=2,"sesamo (tracce)","")),IF(AU23=1,"sedano",IF(AU23=2,"sedano (tracce)","")),IF(AV23=1,"senape",IF(AV23=2,"senape (tracce)","")),IF(AW23=1,"solfiti",IF(AW23=2,"solfiti (tracce)","")),IF(AX23=1,"lupini",IF(AX23=2,"lupini (tracce)","")),IF(AY23=1,"nichel",IF(AY23=2,"nichel (tracce)","")),IF(AZ23=1,"FODMAP",IF(AZ23=2,"FODMAP (tracce)",""))) | BB23: =ROUND(4*C23+4*D23+9*E23+2*N(F23),0) -> 100 | BC23: CREA – Tabelle di composizione degli alimenti
A24: Petto di tacchino | B24: 107 | C24: 0 | D24: 24 | E24: 1.2 | F24: 0 | G24: 0 | H24: 0.4 | I24: 0.3 | J24: 0.3 | K24: 50 | L24: 42 | M24: 360 | N24: 9 | O24: 210 | P24: 27 | Q24: 0.9 | R24: 1.2 | S24: 0 | T24: 0 | U24: 0.1 | V24: 0.1 | W24: 0.05 | X24: 0.13 | Y24: 9 | Z24: 0.65 | AA24: 7 | AB24: 0.4 | AC24: Carni | AD24: petto_di_tacchino | AE24: proteine | AF24: crudo | AJ24: 0 | AK24: 0 | AL24: 0 | AM24: 0 | AN24: 0 | AO24: 0 | AP24: 0 | AQ24: 0 | AR24: 0 | AS24: 0 | AT24: 0 | AU24: 0 | AV24: 0 | AW24: 0 | AX24: 0 | AY24: 0 | AZ24: 0 | BA24: =_xlfn.TEXTJOIN(", ",TRUE(),IF(AJ24=1,"glutine",IF(AJ24=2,"glutine (tracce)","")),IF(AK24=1,"latte",IF(AK24=2,"latte (tracce)","")),IF(AL24=1,"lattosio",IF(AL24=2,"lattosio (tracce)","")),IF(AM24=1,"uova",IF(AM24=2,"uova (tracce)","")),IF(AN24=1,"pesce",IF(AN24=2,"pesce (tracce)","")),IF(AO24=1,"crostacei",IF(AO24=2,"crostacei (tracce)","")),IF(AP24=1,"molluschi",IF(AP24=2,"molluschi (tracce)","")),IF(AQ24=1,"frutta a guscio",IF(AQ24=2,"frutta a guscio (tracce)","")),IF(AR24=1,"arachidi",IF(AR24=2,"arachidi (tracce)","")),IF(AS24=1,"soia",IF(AS24=2,"soia (tracce)","")),IF(AT24=1,"sesamo",IF(AT24=2,"sesamo (tracce)","")),IF(AU24=1,"sedano",IF(AU24=2,"sedano (tracce)","")),IF(AV24=1,"senape",IF(AV24=2,"senape (tracce)","")),IF(AW24=1,"solfiti",IF(AW24=2,"solfiti (tracce)","")),IF(AX24=1,"lupini",IF(AX24=2,"lupini (tracce)","")),IF(AY24=1,"nichel",IF(AY24=2,"nichel (tracce)","")),IF(AZ24=1,"FODMAP",IF(AZ24=2,"FODMAP (tracce)",""))) | BB24: =ROUND(4*C24+4*D24+9*E24+2*N(F24),0) -> 107 | BC24: CREA – Tabelle di composizione degli alimenti
A25: Coscia di pollo (senza pelle) | B25: 121 | C25: 0 | D25: 19.7 | E25: 4.1 | F25: 0 | G25: 0 | H25: 1 | I25: 1.25 | J25: 0.9 | K25: 94 | L25: 95 | M25: 237 | N25: 9 | O25: 186 | P25: 23 | Q25: 0.8 | R25: 1.6 | S25: 18 | T25: 0 | U25: 0.1 | V25: 0.2 | W25: 0.08 | X25: 0.18 | Y25: 5.8 | Z25: 0.42 | AA25: 9 | AB25: 0.5 | AC25: Carni | AD25: coscia_di_pollo_senza_pelle | AE25: proteine | AF25: crudo | AJ25: 0 | AK25: 0 | AL25: 0 | AM25: 0 | AN25: 0 | AO25: 0 | AP25: 0 | AQ25: 0 | AR25: 0 | AS25: 0 | AT25: 0 | AU25: 0 | AV25: 0 | AW25: 0 | AX25: 0 | AY25: 0 | AZ25: 0 | BA25: =_xlfn.TEXTJOIN(", ",TRUE(),IF(AJ25=1,"glutine",IF(AJ25=2,"glutine (tracce)","")),IF(AK25=1,"latte",IF(AK25=2,"latte (tracce)","")),IF(AL25=1,"lattosio",IF(AL25=2,"lattosio (tracce)","")),IF(AM25=1,"uova",IF(AM25=2,"uova (tracce)","")),IF(AN25=1,"pesce",IF(AN25=2,"pesce (tracce)","")),IF(AO25=1,"crostacei",IF(AO25=2,"crostacei (tracce)","")),IF(AP25=1,"molluschi",IF(AP25=2,"molluschi (tracce)","")),IF(AQ25=1,"frutta a guscio",IF(AQ25=2,"frutta a guscio (tracce)","")),IF(AR25=1,"arachidi",IF(AR25=2,"arachidi (tracce)","")),IF(AS25=1,"soia",IF(AS25=2,"soia (tracce)","")),IF(AT25=1,"sesamo",IF(AT25=2,"sesamo (tracce)","")),IF(AU25=1,"sedano",IF(AU25=2,"sedano (tracce)","")),IF(AV25=1,"senape",IF(AV25=2,"senape (tracce)","")),IF(AW25=1,"solfiti",IF(AW25=2,"solfiti (tracce)","")),IF(AX25=1,"lupini",IF(AX25=2,"lupini (tracce)","")),IF(AY25=1,"nichel",IF(AY25=2,"nichel (tracce)","")),IF(AZ25=1,"FODMAP",IF(AZ25=2,"FODMAP (tracce)",""))) | BB25: =ROUND(4*C25+4*D25+9*E25+2*N(F25),0) -> 116 | BC25: USDA FoodData Central – SR Legacy
A26: Manzo magro (girello/fesa) | B26: 113 | C26: 0 | D26: 21.8 | E26: 2.9 | F26: 0 | G26: 0 | H26: 1.1 | I26: 1.2 | J26: 0.15 | K26: 60 | L26: 50 | M26: 330 | N26: 5 | O26: 200 | P26: 22 | Q26: 1.9 | R26: 4 | S26: 0 | T26: 0 | U26: 0.1 | V26: 0.3 | W26: 0.08 | X26: 0.17 | Y26: 5.5 | Z26: 0.5 | AA26: 8 | AB26: 2 | AC26: Carni | AD26: manzo_magro_girello_fesa | AE26: proteine | AF26: crudo | AJ26: 0 | AK26: 0 | AL26: 0 | AM26: 0 | AN26: 0 | AO26: 0 | AP26: 0 | AQ26: 0 | AR26: 0 | AS26: 0 | AT26: 0 | AU26: 0 | AV26: 0 | AW26: 0 | AX26: 0 | AY26: 0 | AZ26: 0 | BA26: =_xlfn.TEXTJOIN(", ",TRUE(),IF(AJ26=1,"glutine",IF(AJ26=2,"glutine (tracce)","")),IF(AK26=1,"latte",IF(AK26=2,"latte (tracce)","")),IF(AL26=1,"lattosio",IF(AL26=2,"lattosio (tracce)","")),IF(AM26=1,"uova",IF(AM26=2,"uova (tracce)","")),IF(AN26=1,"pesce",IF(AN26=2,"pesce (tracce)","")),IF(AO26=1,"crostacei",IF(AO26=2,"crostacei (tracce)","")),IF(AP26=1,"molluschi",IF(AP26=2,"molluschi (tracce)","")),IF(AQ26=1,"frutta a guscio",IF(AQ26=2,"frutta a guscio (tracce)","")),IF(AR26=1,"arachidi",IF(AR26=2,"arachidi (tracce)","")),IF(AS26=1,"soia",IF(AS26=2,"soia (tracce)","")),IF(AT26=1,"sesamo",IF(AT26=2,"sesamo (tracce)","")),IF(AU26=1,"sedano",IF(AU26=2,"sedano (tracce)","")),IF(AV26=1,"senape",IF(AV26=2,"senape (tracce)","")),IF(AW26=1,"solfiti",IF(AW26=2,"solfiti (tracce)","")),IF(AX26=1,"lupini",IF(AX26=2,"lupini (tracce)","")),IF(AY26=1,"nichel",IF(AY26=2,"nichel (tracce)","")),IF(AZ26=1,"FODMAP",IF(AZ26=2,"FODMAP (tracce)",""))) | BB26: =ROUND(4*C26+4*D26+9*E26+2*N(F26),0) -> 113 | BC26: CREA – Tabelle di composizione degli alimenti
A27: Macinato di manzo magro (5% grassi) | B27: 137 | C27: 0 | D27: 21.4 | E27: 5 | F27: 0 | G27: 0 | H27: 2.3 | I27: 2.1 | J27: 0.3 | K27: 62 | L27: 66 | M27: 343 | N27: 6 | O27: 199 | P27: 21 | Q27: 2.4 | R27: 5.4 | S27: 0 | T27: 0 | U27: 0.1 | V27: 0.2 | W27: 0.05 | X27: 0.16 | Y27: 6 | Z27: 0.37 | AA27: 7 | AB27: 2.2 | AC27: Carni | AD27: macinato_di_manzo_magro_5_grassi | AE27: proteine | AF27: crudo | AJ27: 0 | AK27: 0 | AL27: 0 | AM27: 0 | AN27: 0 | AO27: 0 | AP27: 0 | AQ27: 0 | AR27: 0 | AS27: 0 | AT27: 0 | AU27: 0 | AV27: 0 | AW27: 0 | AX27: 0 | AY27: 0 | AZ27: 0 | BA27: =_xlfn.TEXTJOIN(", ",TRUE(),IF(AJ27=1,"glutine",IF(AJ27=2,"glutine (tracce)","")),IF(AK27=1,"latte",IF(AK27=2,"latte (tracce)","")),IF(AL27=1,"lattosio",IF(AL27=2,"lattosio (tracce)","")),IF(AM27=1,"uova",IF(AM27=2,"uova (tracce)","")),IF(AN27=1,"pesce",IF(AN27=2,"pesce (tracce)","")),IF(AO27=1,"crostacei",IF(AO27=2,"crostacei (tracce)","")),IF(AP27=1,"molluschi",IF(AP27=2,"molluschi (tracce)","")),IF(AQ27=1,"frutta a guscio",IF(AQ27=2,"frutta a guscio (tracce)","")),IF(AR27=1,"arachidi",IF(AR27=2,"arachidi (tracce)","")),IF(AS27=1,"soia",IF(AS27=2,"soia (tracce)","")),IF(AT27=1,"sesamo",IF(AT27=2,"sesamo (tracce)","")),IF(AU27=1,"sedano",IF(AU27=2,"sedano (tracce)","")),IF(AV27=1,"senape",IF(AV27=2,"senape (tracce)","")),IF(AW27=1,"solfiti",IF(AW27=2,"solfiti (tracce)","")),IF(AX27=1,"lupini",IF(AX27=2,"lupini (tracce)","")),IF(AY27=1,"nichel",IF(AY27=2,"nichel (tracce)","")),IF(AZ27=1,"FODMAP",IF(AZ27=2,"FODMAP (tracce)",""))) | BB27: =ROUND(4*C27+4*D27+9*E27+2*N(F27),0) -> 131 | BC27: USDA FoodData Central – SR Legacy
A28: Vitello (fesa) | B28: 92 | C28: 0 | D28: 20.7 | E28: 1 | F28: 0 | G28: 0 | H28: 0.4 | I28: 0.3 | J28: 0.2 | K28: 70 | L28: 50 | M28: 340 | N28: 7 | O28: 190 | P28: 20 | Q28: 0.8 | R28: 3 | S28: 0 | T28: 0 | U28: 0.1 | V28: 0.2 | W28: 0.07 | X28: 0.2 | Y28: 6.8 | Z28: 0.5 | AA28: 15 | AB28: 1.2 | AC28: Carni | AD28: vitello_fesa | AE28: proteine | AF28: crudo | AJ28: 0 | AK28: 0 | AL28: 0 | AM28: 0 | AN28: 0 | AO28: 0 | AP28: 0 | AQ28: 0 | AR28: 0 | AS28: 0 | AT28: 0 | AU28: 0 | AV28: 0 | AW28: 0 | AX28: 0 | AY28: 0 | AZ28: 0 | BA28: =_xlfn.TEXTJOIN(", ",TRUE(),IF(AJ28=1,"glutine",IF(AJ28=2,"glutine (tracce)","")),IF(AK28=1,"latte",IF(AK28=2,"latte (tracce)","")),IF(AL28=1,"lattosio",IF(AL28=2,"lattosio (tracce)","")),IF(AM28=1,"uova",IF(AM28=2,"uova (tracce)","")),IF(AN28=1,"pesce",IF(AN28=2,"pesce (tracce)","")),IF(AO28=1,"crostacei",IF(AO28=2,"crostacei (tracce)","")),IF(AP28=1,"molluschi",IF(AP28=2,"molluschi (tracce)","")),IF(AQ28=1,"frutta a guscio",IF(AQ28=2,"frutta a guscio (tracce)","")),IF(AR28=1,"arachidi",IF(AR28=2,"arachidi (tracce)","")),IF(AS28=1,"soia",IF(AS28=2,"soia (tracce)","")),IF(AT28=1,"sesamo",IF(AT28=2,"sesamo (tracce)","")),IF(AU28=1,"sedano",IF(AU28=2,"sedano (tracce)","")),IF(AV28=1,"senape",IF(AV28=2,"senape (tracce)","")),IF(AW28=1,"solfiti",IF(AW28=2,"solfiti (tracce)","")),IF(AX28=1,"lupini",IF(AX28=2,"lupini (tracce)","")),IF(AY28=1,"nichel",IF(AY28=2,"nichel (tracce)","")),IF(AZ28=1,"FODMAP",IF(AZ28=2,"FODMAP (tracce)",""))) | BB28: =ROUND(4*C28+4*D28+9*E28+2*N(F28),0) -> 92 | BC28: CREA – Tabelle di composizione degli alimenti
A29: Lonza di maiale | B29: 138 | C29: 0 | D29: 21.4 | E29: 5.8 | F29: 0 | G29: 0 | H29: 2 | I29: 2.5 | J29: 0.7 | K29: 62 | L29: 52 | M29: 360 | N29: 6 | O29: 220 | P29: 25 | Q29: 0.8 | R29: 1.9 | S29: 2 | T29: 0 | U29: 0.6 | V29: 0.2 | W29: 0.9 | X29: 0.25 | Y29: 7 | Z29: 0.6 | AA29: 1 | AB29: 0.6 | AC29: Carni | AD29: lonza_di_maiale | AE29: proteine | AF29: crudo | AJ29: 0 | AK29: 0 | AL29: 0 | AM29: 0 | AN29: 0 | AO29: 0 | AP29: 0 | AQ29: 0 | AR29: 0 | AS29: 0 | AT29: 0 | AU29: 0 | AV29: 0 | AW29: 0 | AX29: 0 | AY29: 0 | AZ29: 0 | BA29: =_xlfn.TEXTJOIN(", ",TRUE(),IF(AJ29=1,"glutine",IF(AJ29=2,"glutine (tracce)","")),IF(AK29=1,"latte",IF(AK29=2,"latte (tracce)","")),IF(AL29=1,"lattosio",IF(AL29=2,"lattosio (tracce)","")),IF(AM29=1,"uova",IF(AM29=2,"uova (tracce)","")),IF(AN29=1,"pesce",IF(AN29=2,"pesce (tracce)","")),IF(AO29=1,"crostacei",IF(AO29=2,"crostacei (tracce)","")),IF(AP29=1,"molluschi",IF(AP29=2,"molluschi (tracce)","")),IF(AQ29=1,"frutta a guscio",IF(AQ29=2,"frutta a guscio (tracce)","")),IF(AR29=1,"arachidi",IF(AR29=2,"arachidi (tracce)","")),IF(AS29=1,"soia",IF(AS29=2,"soia (tracce)","")),IF(AT29=1,"sesamo",IF(AT29=2,"sesamo (tracce)","")),IF(AU29=1,"sedano",IF(AU29=2,"sedano (tracce)","")),IF(AV29=1,"senape",IF(AV29=2,"senape (tracce)","")),IF(AW29=1,"solfiti",IF(AW29=2,"solfiti (tracce)","")),IF(AX29=1,"lupini",IF(AX29=2,"lupini (tracce)","")),IF(AY29=1,"nichel",IF(AY29=2,"nichel (tracce)","")),IF(AZ29=1,"FODMAP",IF(AZ29=2,"FODMAP (tracce)",""))) | BB29: =ROUND(4*C29+4*D29+9*E29+2*N(F29),0) -> 138 | BC29: USDA FoodData Central – SR Legacy
A30: Filetto di maiale | B30: 120 | C30: 0 | D30: 21 | E30: 3.4 | F30: 0 | G30: 0 | H30: 1.2 | I30: 1.4 | J30: 0.4 | K30: 65 | L30: 53 | M30: 400 | N30: 5 | O30: 240 | P30: 27 | Q30: 1 | R30: 1.9 | S30: 0 | T30: 0 | U30: 0.5 | V30: 0.2 | W30: 0.98 | X30: 0.34 | Y30: 6.7 | Z30: 0.78 | AA30: 0 | AB30: 0.5 | AC30: Carni | AD30: filetto_di_maiale | AE30: proteine | AF30: crudo | AJ30: 0 | AK30: 0 | AL30: 0 | AM30: 0 | AN30: 0 | AO30: 0 | AP30: 0 | AQ30: 0 | AR30: 0 | AS30: 0 | AT30: 0 | AU30: 0 | AV30: 0 | AW30: 0 | AX30: 0 | AY30: 0 | AZ30: 0 | BA30: =_xlfn.TEXTJOIN(", ",TRUE(),IF(AJ30=1,"glutine",IF(AJ30=2,"glutine (tracce)","")),IF(AK30=1,"latte",IF(AK30=2,"latte (tracce)","")),IF(AL30=1,"lattosio",IF(AL30=2,"lattosio (tracce)","")),IF(AM30=1,"uova",IF(AM30=2,"uova (tracce)","")),IF(AN30=1,"pesce",IF(AN30=2,"pesce (tracce)","")),IF(AO30=1,"crostacei",IF(AO30=2,"crostacei (tracce)","")),IF(AP30=1,"molluschi",IF(AP30=2,"molluschi (tracce)","")),IF(AQ30=1,"frutta a guscio",IF(AQ30=2,"frutta a guscio (tracce)","")),IF(AR30=1,"arachidi",IF(AR30=2,"arachidi (tracce)","")),IF(AS30=1,"soia",IF(AS30=2,"soia (tracce)","")),IF(AT30=1,"sesamo",IF(AT30=2,"sesamo (tracce)","")),IF(AU30=1,"sedano",IF(AU30=2,"sedano (tracce)","")),IF(AV30=1,"senape",IF(AV30=2,"senape (tracce)","")),IF(AW30=1,"solfiti",IF(AW30=2,"solfiti (tracce)","")),IF(AX30=1,"lupini",IF(AX30=2,"lupini (tracce)","")),IF(AY30=1,"nichel",IF(AY30=2,"nichel (tracce)","")),IF(AZ30=1,"FODMAP",IF(AZ30=2,"FODMAP (tracce)",""))) | BB30: =ROUND(4*C30+4*D30+9*E30+2*N(F30),0) -> 115 | BC30: USDA FoodData Central – SR Legacy
A31: Coniglio | B31: 136 | C31: 0 | D31: 20.1 | E31: 5.6 | F31: 0 | G31: 0 | H31: 1.7 | I31: 1.5 | J31: 1.1 | K31: 57 | L31: 41 | M31: 330 | N31: 13 | O31: 213 | P31: 19 | Q31: 1.57 | R31: 1.57 | S31: 0 | T31: 0 | U31: 0 | V31: 0.1 | W31: 0.1 | X31: 0.15 | Y31: 7.8 | Z31: 0.47 | AA31: 8 | AB31: 7.2 | AC31: Carni | AD31: coniglio | AE31: proteine | AF31: crudo | AJ31: 0 | AK31: 0 | AL31: 0 | AM31: 0 | AN31: 0 | AO31: 0 | AP31: 0 | AQ31: 0 | AR31: 0 | AS31: 0 | AT31: 0 | AU31: 0 | AV31: 0 | AW31: 0 | AX31: 0 | AY31: 0 | AZ31: 0 | BA31: =_xlfn.TEXTJOIN(", ",TRUE(),IF(AJ31=1,"glutine",IF(AJ31=2,"glutine (tracce)","")),IF(AK31=1,"latte",IF(AK31=2,"latte (tracce)","")),IF(AL31=1,"lattosio",IF(AL31=2,"lattosio (tracce)","")),IF(AM31=1,"uova",IF(AM31=2,"uova (tracce)","")),IF(AN31=1,"pesce",IF(AN31=2,"pesce (tracce)","")),IF(AO31=1,"crostacei",IF(AO31=2,"crostacei (tracce)","")),IF(AP31=1,"molluschi",IF(AP31=2,"molluschi (tracce)","")),IF(AQ31=1,"frutta a guscio",IF(AQ31=2,"frutta a guscio (tracce)","")),IF(AR31=1,"arachidi",IF(AR31=2,"arachidi (tracce)","")),IF(AS31=1,"soia",IF(AS31=2,"soia (tracce)","")),IF(AT31=1,"sesamo",IF(AT31=2,"sesamo (tracce)","")),IF(AU31=1,"sedano",IF(AU31=2,"sedano (tracce)","")),IF(AV31=1,"senape",IF(AV31=2,"senape (tracce)","")),IF(AW31=1,"solfiti",IF(AW31=2,"solfiti (tracce)","")),IF(AX31=1,"lupini",IF(AX31=2,"lupini (tracce)","")),IF(AY31=1,"nichel",IF(AY31=2,"nichel (tracce)","")),IF(AZ31=1,"FODMAP",IF(AZ31=2,"FODMAP (tracce)",""))) | BB31: =ROUND(4*C31+4*D31+9*E31+2*N(F31),0) -> 131 | BC31: USDA FoodData Central – SR Legacy
A32: Cavallo | B32: 133 | C32: 0.5 | D32: 21.4 | E32: 4.6 | F32: 0 | G32: 0 | H32: 1.4 | I32: 1.6 | J32: 1 | K32: 52 | L32: 53 | M32: 360 | N32: 6 | O32: 221 | P32: 24 | Q32: 3.8 | R32: 2.9 | S32: 0 | T32: 1 | W32: 0.13 | X32: 0.1 | Y32: 4.6 | Z32: 0.38 | AA32: 5 | AB32: 3 | AC32: Carni | AD32: cavallo | AE32: proteine | AF32: crudo | AJ32: 0 | AK32: 0 | AL32: 0 | AM32: 0 | AN32: 0 | AO32: 0 | AP32: 0 | AQ32: 0 | AR32: 0 | AS32: 0 | AT32: 0 | AU32: 0 | AV32: 0 | AW32: 0 | AX32: 0 | AY32: 0 | AZ32: 0 | BA32: =_xlfn.TEXTJOIN(", ",TRUE(),IF(AJ32=1,"glutine",IF(AJ32=2,"glutine (tracce)","")),IF(AK32=1,"latte",IF(AK32=2,"latte (tracce)","")),IF(AL32=1,"lattosio",IF(AL32=2,"lattosio (tracce)","")),IF(AM32=1,"uova",IF(AM32=2,"uova (tracce)","")),IF(AN32=1,"pesce",IF(AN32=2,"pesce (tracce)","")),IF(AO32=1,"crostacei",IF(AO32=2,"crostacei (tracce)","")),IF(AP32=1,"molluschi",IF(AP32=2,"molluschi (tracce)","")),IF(AQ32=1,"frutta a guscio",IF(AQ32=2,"frutta a guscio (tracce)","")),IF(AR32=1,"arachidi",IF(AR32=2,"arachidi (tracce)","")),IF(AS32=1,"soia",IF(AS32=2,"soia (tracce)","")),IF(AT32=1,"sesamo",IF(AT32=2,"sesamo (tracce)","")),IF(AU32=1,"sedano",IF(AU32=2,"sedano (tracce)","")),IF(AV32=1,"senape",IF(AV32=2,"senape (tracce)","")),IF(AW32=1,"solfiti",IF(AW32=2,"solfiti (tracce)","")),IF(AX32=1,"lupini",IF(AX32=2,"lupini (tracce)","")),IF(AY32=1,"nichel",IF(AY32=2,"nichel (tracce)","")),IF(AZ32=1,"FODMAP",IF(AZ32=2,"FODMAP (tracce)",""))) | BB32: =ROUND(4*C32+4*D32+9*E32+2*N(F32),0) -> 129 | BC32: USDA FoodData Central – SR Legacy
A33: Bresaola | B33: 151 | C33: 0.4 | D33: 32 | E33: 2.6 | F33: 0 | G33: 0.4 | H33: 0.9 | I33: 1 | J33: 0.3 | K33: 67 | L33: 1597 | M33: 505 | N33: 16 | O33: 263 | P33: 35 | Q33: 2.8 | R33: 7.4 | S33: 0 | T33: 0 | W33: 0.05 | X33: 0.2 | Y33: 9 | Z33: 0.4 | AB33: 1.5 | AC33: Salumi | AD33: bresaola | AE33: proteine | AF33: stagionato | AJ33: 0 | AK33: 0 | AL33: 0 | AM33: 0 | AN33: 0 | AO33: 0 | AP33: 0 | AQ33: 0 | AR33: 0 | AS33: 0 | AT33: 0 | AU33: 0 | AV33: 0 | AW33: 0 | AX33: 0 | AY33: 0 | AZ33: 0 | BA33: =_xlfn.TEXTJOIN(", ",TRUE(),IF(AJ33=1,"glutine",IF(AJ33=2,"glutine (tracce)","")),IF(AK33=1,"latte",IF(AK33=2,"latte (tracce)","")),IF(AL33=1,"lattosio",IF(AL33=2,"lattosio (tracce)","")),IF(AM33=1,"uova",IF(AM33=2,"uova (tracce)","")),IF(AN33=1,"pesce",IF(AN33=2,"pesce (tracce)","")),IF(AO33=1,"crostacei",IF(AO33=2,"crostacei (tracce)","")),IF(AP33=1,"molluschi",IF(AP33=2,"molluschi (tracce)","")),IF(AQ33=1,"frutta a guscio",IF(AQ33=2,"frutta a guscio (tracce)","")),IF(AR33=1,"arachidi",IF(AR33=2,"arachidi (tracce)","")),IF(AS33=1,"soia",IF(AS33=2,"soia (tracce)","")),IF(AT33=1,"sesamo",IF(AT33=2,"sesamo (tracce)","")),IF(AU33=1,"sedano",IF(AU33=2,"sedano (tracce)","")),IF(AV33=1,"senape",IF(AV33=2,"senape (tracce)","")),IF(AW33=1,"solfiti",IF(AW33=2,"solfiti (tracce)","")),IF(AX33=1,"lupini",IF(AX33=2,"lupini (tracce)","")),IF(AY33=1,"nichel",IF(AY33=2,"nichel (tracce)","")),IF(AZ33=1,"FODMAP",IF(AZ33=2,"FODMAP (tracce)",""))) | BB33: =ROUND(4*C33+4*D33+9*E33+2*N(F33),0) -> 153 | BC33: CREA – Tabelle di composizione degli alimenti
A34: Fesa di tacchino al forno (affettato) | B34: 100 | C34: 1 | D34: 21.5 | E34: 1.4 | F34: 0 | G34: 0.5 | H34: 0.5 | K34: 45 | L34: 800 | AC34: Salumi | AD34: fesa_di_tacchino_al_forno_affettato | AE34: proteine | AF34: cotto | AJ34: 0 | AK34: 0 | AL34: 0 | AM34: 0 | AN34: 0 | AO34: 0 | AP34: 0 | AQ34: 0 | AR34: 0 | AS34: 0 | AT34: 0 | AU34: 0 | AV34: 0 | AW34: 0 | AX34: 0 | AY34: 0 | AZ34: 0 | BA34: =_xlfn.TEXTJOIN(", ",TRUE(),IF(AJ34=1,"glutine",IF(AJ34=2,"glutine (tracce)","")),IF(AK34=1,"latte",IF(AK34=2,"latte (tracce)","")),IF(AL34=1,"lattosio",IF(AL34=2,"lattosio (tracce)","")),IF(AM34=1,"uova",IF(AM34=2,"uova (tracce)","")),IF(AN34=1,"pesce",IF(AN34=2,"pesce (tracce)","")),IF(AO34=1,"crostacei",IF(AO34=2,"crostacei (tracce)","")),IF(AP34=1,"molluschi",IF(AP34=2,"molluschi (tracce)","")),IF(AQ34=1,"frutta a guscio",IF(AQ34=2,"frutta a guscio (tracce)","")),IF(AR34=1,"arachidi",IF(AR34=2,"arachidi (tracce)","")),IF(AS34=1,"soia",IF(AS34=2,"soia (tracce)","")),IF(AT34=1,"sesamo",IF(AT34=2,"sesamo (tracce)","")),IF(AU34=1,"sedano",IF(AU34=2,"sedano (tracce)","")),IF(AV34=1,"senape",IF(AV34=2,"senape (tracce)","")),IF(AW34=1,"solfiti",IF(AW34=2,"solfiti (tracce)","")),IF(AX34=1,"lupini",IF(AX34=2,"lupini (tracce)","")),IF(AY34=1,"nichel",IF(AY34=2,"nichel (tracce)","")),IF(AZ34=1,"FODMAP",IF(AZ34=2,"FODMAP (tracce)",""))) | BB34: =ROUND(4*C34+4*D34+9*E34+2*N(F34),0) -> 103 | BC34: Media etichette prodotti commerciali (IT)
A35: Prosciutto crudo sgrassato | B35: 177 | C35: 0 | D35: 27.8 | E35: 7.3 | F35: 0 | G35: 0 | H35: 2.5 | I35: 3.3 | J35: 1 | K35: 70 | L35: 2000 | M35: 450 | N35: 10 | O35: 250 | P35: 25 | Q35: 1.2 | R35: 2.8 | S35: 0 | T35: 0 | U35: 0.5 | V35: 0.1 | W35: 0.8 | X35: 0.2 | Y35: 6 | Z35: 0.4 | AA35: 3 | AB35: 1 | AC35: Salumi | AD35: prosciutto_crudo_sgrassato | AE35: proteine | AF35: stagionato | AJ35: 0 | AK35: 0 | AL35: 0 | AM35: 0 | AN35: 0 | AO35: 0 | AP35: 0 | AQ35: 0 | AR35: 0 | AS35: 0 | AT35: 0 | AU35: 0 | AV35: 0 | AW35: 0 | AX35: 0 | AY35: 0 | AZ35: 0 | BA35: =_xlfn.TEXTJOIN(", ",TRUE(),IF(AJ35=1,"glutine",IF(AJ35=2,"glutine (tracce)","")),IF(AK35=1,"latte",IF(AK35=2,"latte (tracce)","")),IF(AL35=1,"lattosio",IF(AL35=2,"lattosio (tracce)","")),IF(AM35=1,"uova",IF(AM35=2,"uova (tracce)","")),IF(AN35=1,"pesce",IF(AN35=2,"pesce (tracce)","")),IF(AO35=1,"crostacei",IF(AO35=2,"crostacei (tracce)","")),IF(AP35=1,"molluschi",IF(AP35=2,"molluschi (tracce)","")),IF(AQ35=1,"frutta a guscio",IF(AQ35=2,"frutta a guscio (tracce)","")),IF(AR35=1,"arachidi",IF(AR35=2,"arachidi (tracce)","")),IF(AS35=1,"soia",IF(AS35=2,"soia (tracce)","")),IF(AT35=1,"sesamo",IF(AT35=2,"sesamo (tracce)","")),IF(AU35=1,"sedano",IF(AU35=2,"sedano (tracce)","")),IF(AV35=1,"senape",IF(AV35=2,"senape (tracce)","")),IF(AW35=1,"solfiti",IF(AW35=2,"solfiti (tracce)","")),IF(AX35=1,"lupini",IF(AX35=2,"lupini (tracce)","")),IF(AY35=1,"nichel",IF(AY35=2,"nichel (tracce)","")),IF(AZ35=1,"FODMAP",IF(AZ35=2,"FODMAP (tracce)",""))) | BB35: =ROUND(4*C35+4*D35+9*E35+2*N(F35),0) -> 177 | BC35: CREA – Tabelle di composizione degli alimenti
A36: Prosciutto cotto alta qualità | B36: 143 | C36: 1 | D36: 19 | E36: 7 | F36: 0 | G36: 1 | H36: 2.5 | K36: 60 | L36: 800 | AC36: Salumi | AD36: prosciutto_cotto_alta_qualita | AE36: proteine | AF36: cotto | AJ36: 0 | AK36: 0 | AL36: 0 | AM36: 0 | AN36: 0 | AO36: 0 | AP36: 0 | AQ36: 0 | AR36: 0 | AS36: 0 | AT36: 0 | AU36: 0 | AV36: 0 | AW36: 0 | AX36: 0 | AY36: 0 | AZ36: 0 | BA36: =_xlfn.TEXTJOIN(", ",TRUE(),IF(AJ36=1,"glutine",IF(AJ36=2,"glutine (tracce)","")),IF(AK36=1,"latte",IF(AK36=2,"latte (tracce)","")),IF(AL36=1,"lattosio",IF(AL36=2,"lattosio (tracce)","")),IF(AM36=1,"uova",IF(AM36=2,"uova (tracce)","")),IF(AN36=1,"pesce",IF(AN36=2,"pesce (tracce)","")),IF(AO36=1,"crostacei",IF(AO36=2,"crostacei (tracce)","")),IF(AP36=1,"molluschi",IF(AP36=2,"molluschi (tracce)","")),IF(AQ36=1,"frutta a guscio",IF(AQ36=2,"frutta a guscio (tracce)","")),IF(AR36=1,"arachidi",IF(AR36=2,"arachidi (tracce)","")),IF(AS36=1,"soia",IF(AS36=2,"soia (tracce)","")),IF(AT36=1,"sesamo",IF(AT36=2,"sesamo (tracce)","")),IF(AU36=1,"sedano",IF(AU36=2,"sedano (tracce)","")),IF(AV36=1,"senape",IF(AV36=2,"senape (tracce)","")),IF(AW36=1,"solfiti",IF(AW36=2,"solfiti (tracce)","")),IF(AX36=1,"lupini",IF(AX36=2,"lupini (tracce)","")),IF(AY36=1,"nichel",IF(AY36=2,"nichel (tracce)","")),IF(AZ36=1,"FODMAP",IF(AZ36=2,"FODMAP (tracce)",""))) | BB36: =ROUND(4*C36+4*D36+9*E36+2*N(F36),0) -> 143 | BC36: Media etichette prodotti commerciali (IT)
A37: Merluzzo | B37: 82 | C37: 0 | D37: 17.8 | E37: 0.7 | F37: 0 | G37: 0 | H37: 0.13 | I37: 0.09 | J37: 0.23 | K37: 43 | L37: 54 | M37: 413 | N37: 16 | O37: 203 | P37: 32 | Q37: 0.38 | R37: 0.45 | S37: 12 | T37: 1 | U37: 0.9 | V37: 0.64 | W37: 0.08 | X37: 0.07 | Y37: 2.06 | Z37: 0.25 | AA37: 7 | AB37: 0.91 | AC37: Pesce | AD37: merluzzo | AE37: proteine | AF37: crudo | AJ37: 0 | AK37: 0 | AL37: 0 | AM37: 0 | AN37: 1 | AO37: 0 | AP37: 0 | AQ37: 0 | AR37: 0 | AS37: 0 | AT37: 0 | AU37: 0 | AV37: 0 | AW37: 0 | AX37: 0 | AY37: 0 | AZ37: 0 | BA37: =_xlfn.TEXTJOIN(", ",TRUE(),IF(AJ37=1,"glutine",IF(AJ37=2,"glutine (tracce)","")),IF(AK37=1,"latte",IF(AK37=2,"latte (tracce)","")),IF(AL37=1,"lattosio",IF(AL37=2,"lattosio (tracce)","")),IF(AM37=1,"uova",IF(AM37=2,"uova (tracce)","")),IF(AN37=1,"pesce",IF(AN37=2,"pesce (tracce)","")),IF(AO37=1,"crostacei",IF(AO37=2,"crostacei (tracce)","")),IF(AP37=1,"molluschi",IF(AP37=2,"molluschi (tracce)","")),IF(AQ37=1,"frutta a guscio",IF(AQ37=2,"frutta a guscio (tracce)","")),IF(AR37=1,"arachidi",IF(AR37=2,"arachidi (tracce)","")),IF(AS37=1,"soia",IF(AS37=2,"soia (tracce)","")),IF(AT37=1,"sesamo",IF(AT37=2,"sesamo (tracce)","")),IF(AU37=1,"sedano",IF(AU37=2,"sedano (tracce)","")),IF(AV37=1,"senape",IF(AV37=2,"senape (tracce)","")),IF(AW37=1,"solfiti",IF(AW37=2,"solfiti (tracce)","")),IF(AX37=1,"lupini",IF(AX37=2,"lupini (tracce)","")),IF(AY37=1,"nichel",IF(AY37=2,"nichel (tracce)","")),IF(AZ37=1,"FODMAP",IF(AZ37=2,"FODMAP (tracce)",""))) -> pesce | BB37: =ROUND(4*C37+4*D37+9*E37+2*N(F37),0) -> 78 | BC37: USDA FoodData Central – SR Legacy
A38: Nasello | B38: 71 | C38: 0 | D38: 17 | E38: 0.3 | F38: 0 | G38: 0 | H38: 0.06 | I38: 0.05 | J38: 0.1 | K38: 50 | L38: 100 | M38: 330 | N38: 30 | O38: 200 | P38: 25 | Q38: 0.4 | R38: 0.4 | S38: 10 | T38: 0 | U38: 0.9 | V38: 0.5 | W38: 0.06 | X38: 0.1 | Y38: 2 | Z38: 0.2 | AA38: 7 | AB38: 1 | AC38: Pesce | AD38: nasello | AE38: proteine | AF38: crudo | AJ38: 0 | AK38: 0 | AL38: 0 | AM38: 0 | AN38: 1 | AO38: 0 | AP38: 0 | AQ38: 0 | AR38: 0 | AS38: 0 | AT38: 0 | AU38: 0 | AV38: 0 | AW38: 0 | AX38: 0 | AY38: 0 | AZ38: 0 | BA38: =_xlfn.TEXTJOIN(", ",TRUE(),IF(AJ38=1,"glutine",IF(AJ38=2,"glutine (tracce)","")),IF(AK38=1,"latte",IF(AK38=2,"latte (tracce)","")),IF(AL38=1,"lattosio",IF(AL38=2,"lattosio (tracce)","")),IF(AM38=1,"uova",IF(AM38=2,"uova (tracce)","")),IF(AN38=1,"pesce",IF(AN38=2,"pesce (tracce)","")),IF(AO38=1,"crostacei",IF(AO38=2,"crostacei (tracce)","")),IF(AP38=1,"molluschi",IF(AP38=2,"molluschi (tracce)","")),IF(AQ38=1,"frutta a guscio",IF(AQ38=2,"frutta a guscio (tracce)","")),IF(AR38=1,"arachidi",IF(AR38=2,"arachidi (tracce)","")),IF(AS38=1,"soia",IF(AS38=2,"soia (tracce)","")),IF(AT38=1,"sesamo",IF(AT38=2,"sesamo (tracce)","")),IF(AU38=1,"sedano",IF(AU38=2,"sedano (tracce)","")),IF(AV38=1,"senape",IF(AV38=2,"senape (tracce)","")),IF(AW38=1,"solfiti",IF(AW38=2,"solfiti (tracce)","")),IF(AX38=1,"lupini",IF(AX38=2,"lupini (tracce)","")),IF(AY38=1,"nichel",IF(AY38=2,"nichel (tracce)","")),IF(AZ38=1,"FODMAP",IF(AZ38=2,"FODMAP (tracce)",""))) -> pesce | BB38: =ROUND(4*C38+4*D38+9*E38+2*N(F38),0) -> 71 | BC38: CREA – Tabelle di composizione degli alimenti
